[2023-05-04T04:38:12.915+0000] {taskinstance.py:1087} INFO - Dependencies all met for <TaskInstance: evidently_drift_report.drift_analysis_execute scheduled__2023-05-03T00:00:00+00:00 [queued]>
[2023-05-04T04:38:12.929+0000] {taskinstance.py:1087} INFO - Dependencies all met for <TaskInstance: evidently_drift_report.drift_analysis_execute scheduled__2023-05-03T00:00:00+00:00 [queued]>
[2023-05-04T04:38:12.929+0000] {taskinstance.py:1283} INFO - 
--------------------------------------------------------------------------------
[2023-05-04T04:38:12.929+0000] {taskinstance.py:1284} INFO - Starting attempt 2 of 2
[2023-05-04T04:38:12.929+0000] {taskinstance.py:1285} INFO - 
--------------------------------------------------------------------------------
[2023-05-04T04:38:12.945+0000] {taskinstance.py:1304} INFO - Executing <Task(PythonOperator): drift_analysis_execute> on 2023-05-03 00:00:00+00:00
[2023-05-04T04:38:12.965+0000] {standard_task_runner.py:55} INFO - Started process 90 to run task
[2023-05-04T04:38:12.970+0000] {standard_task_runner.py:82} INFO - Running: ['***', 'tasks', 'run', 'evidently_drift_report', 'drift_analysis_execute', 'scheduled__2023-05-03T00:00:00+00:00', '--job-id', '103', '--raw', '--subdir', 'DAGS_FOLDER/evidently_drift_report.py', '--cfg-path', '/tmp/tmpzoe73zco']
[2023-05-04T04:38:12.974+0000] {standard_task_runner.py:83} INFO - Job 103: Subtask drift_analysis_execute
[2023-05-04T04:38:13.045+0000] {task_command.py:389} INFO - Running <TaskInstance: evidently_drift_report.drift_analysis_execute scheduled__2023-05-03T00:00:00+00:00 [running]> on host 78523dc16bce
[2023-05-04T04:38:13.125+0000] {taskinstance.py:1511} INFO - Exporting the following env vars:
AIRFLOW_CTX_DAG_OWNER=***
AIRFLOW_CTX_DAG_ID=evidently_drift_report
AIRFLOW_CTX_TASK_ID=drift_analysis_execute
AIRFLOW_CTX_EXECUTION_DATE=2023-05-03T00:00:00+00:00
AIRFLOW_CTX_TRY_NUMBER=2
AIRFLOW_CTX_DAG_RUN_ID=scheduled__2023-05-03T00:00:00+00:00
[2023-05-04T04:38:13.688+0000] {taskinstance.py:1772} ERROR - Task failed with exception
Traceback (most recent call last):
  File "/home/airflow/.local/lib/python3.10/site-packages/airflow/operators/python.py", line 175, in execute
    return_value = self.execute_callable()
  File "/home/airflow/.local/lib/python3.10/site-packages/airflow/operators/python.py", line 192, in execute_callable
    return self.python_callable(*self.op_args, **self.op_kwargs)
  File "/opt/airflow/dags/evidently_drift_report.py", line 35, in drift_analysis_execute
    boston_data_drift_report.run(reference_data=data[:200], current_data=data[200:], column_mapping=data_columns)
  File "/home/airflow/.local/lib/python3.10/site-packages/evidently/report/report.py", line 56, in run
    self._columns_info = process_columns(current_data, column_mapping)
  File "/home/airflow/.local/lib/python3.10/site-packages/evidently/utils/data_operations.py", line 24, in process_columns
    date_column = column_mapping.datetime if column_mapping.datetime in dataset else None
AttributeError: 'Index' object has no attribute 'datetime'
[2023-05-04T04:38:13.706+0000] {taskinstance.py:1322} INFO - Marking task as FAILED. dag_id=evidently_drift_report, task_id=drift_analysis_execute, execution_date=20230503T000000, start_date=20230504T043812, end_date=20230504T043813
[2023-05-04T04:38:13.723+0000] {standard_task_runner.py:100} ERROR - Failed to execute job 103 for task drift_analysis_execute ('Index' object has no attribute 'datetime'; 90)
[2023-05-04T04:38:13.783+0000] {local_task_job.py:159} INFO - Task exited with return code 1
[2023-05-04T04:38:13.851+0000] {taskinstance.py:2582} INFO - 0 downstream tasks scheduled from follow-on schedule check
