[2023-05-04T03:26:32.502+0000] {taskinstance.py:1087} INFO - Dependencies all met for <TaskInstance: train_ml_pipeline.train_model manual__2023-05-04T03:20:16.505818+00:00 [queued]>
[2023-05-04T03:26:32.514+0000] {taskinstance.py:1087} INFO - Dependencies all met for <TaskInstance: train_ml_pipeline.train_model manual__2023-05-04T03:20:16.505818+00:00 [queued]>
[2023-05-04T03:26:32.514+0000] {taskinstance.py:1283} INFO - 
--------------------------------------------------------------------------------
[2023-05-04T03:26:32.514+0000] {taskinstance.py:1284} INFO - Starting attempt 2 of 2
[2023-05-04T03:26:32.514+0000] {taskinstance.py:1285} INFO - 
--------------------------------------------------------------------------------
[2023-05-04T03:26:32.527+0000] {taskinstance.py:1304} INFO - Executing <Task(PythonOperator): train_model> on 2023-05-04 03:20:16.505818+00:00
[2023-05-04T03:26:32.544+0000] {standard_task_runner.py:55} INFO - Started process 77 to run task
[2023-05-04T03:26:32.548+0000] {standard_task_runner.py:82} INFO - Running: ['***', 'tasks', 'run', 'train_ml_pipeline', 'train_model', 'manual__2023-05-04T03:20:16.505818+00:00', '--job-id', '57', '--raw', '--subdir', 'DAGS_FOLDER/machine_learning_trainig_dag_Septembre.py', '--cfg-path', '/tmp/tmpeedynl6c']
[2023-05-04T03:26:32.550+0000] {standard_task_runner.py:83} INFO - Job 57: Subtask train_model
[2023-05-04T03:26:32.610+0000] {task_command.py:389} INFO - Running <TaskInstance: train_ml_pipeline.train_model manual__2023-05-04T03:20:16.505818+00:00 [running]> on host 2b8fae96b182
[2023-05-04T03:26:32.673+0000] {taskinstance.py:1511} INFO - Exporting the following env vars:
AIRFLOW_CTX_DAG_OWNER=***
AIRFLOW_CTX_DAG_ID=train_ml_pipeline
AIRFLOW_CTX_TASK_ID=train_model
AIRFLOW_CTX_EXECUTION_DATE=2023-05-04T03:20:16.505818+00:00
AIRFLOW_CTX_TRY_NUMBER=2
AIRFLOW_CTX_DAG_RUN_ID=manual__2023-05-04T03:20:16.505818+00:00
[2023-05-04T03:26:32.687+0000] {logging_mixin.py:137} INFO - None
[2023-05-04T03:26:32.688+0000] {taskinstance.py:1772} ERROR - Task failed with exception
Traceback (most recent call last):
  File "/home/airflow/.local/lib/python3.10/site-packages/airflow/operators/python.py", line 175, in execute
    return_value = self.execute_callable()
  File "/home/airflow/.local/lib/python3.10/site-packages/airflow/operators/python.py", line 192, in execute_callable
    return self.python_callable(*self.op_args, **self.op_kwargs)
  File "/opt/airflow/dags/script.py", line 47, in train_model
    datetime = datetime.now().strftime("%Y-%m-%d-%H-%M-%S")
UnboundLocalError: local variable 'datetime' referenced before assignment
[2023-05-04T03:26:32.695+0000] {taskinstance.py:1322} INFO - Marking task as FAILED. dag_id=train_ml_pipeline, task_id=train_model, execution_date=20230504T032016, start_date=20230504T032632, end_date=20230504T032632
[2023-05-04T03:26:32.719+0000] {standard_task_runner.py:100} ERROR - Failed to execute job 57 for task train_model (local variable 'datetime' referenced before assignment; 77)
[2023-05-04T03:26:32.759+0000] {local_task_job.py:159} INFO - Task exited with return code 1
[2023-05-04T03:26:32.789+0000] {taskinstance.py:2582} INFO - 0 downstream tasks scheduled from follow-on schedule check
