[2023-05-04T02:20:01.464+0000] {taskinstance.py:1087} INFO - Dependencies all met for <TaskInstance: train_ml_pipeline.train_model scheduled__2023-05-02T00:00:00+00:00 [queued]>
[2023-05-04T02:20:01.479+0000] {taskinstance.py:1087} INFO - Dependencies all met for <TaskInstance: train_ml_pipeline.train_model scheduled__2023-05-02T00:00:00+00:00 [queued]>
[2023-05-04T02:20:01.479+0000] {taskinstance.py:1283} INFO - 
--------------------------------------------------------------------------------
[2023-05-04T02:20:01.479+0000] {taskinstance.py:1284} INFO - Starting attempt 1 of 2
[2023-05-04T02:20:01.479+0000] {taskinstance.py:1285} INFO - 
--------------------------------------------------------------------------------
[2023-05-04T02:20:01.497+0000] {taskinstance.py:1304} INFO - Executing <Task(PythonOperator): train_model> on 2023-05-02 00:00:00+00:00
[2023-05-04T02:20:01.515+0000] {standard_task_runner.py:55} INFO - Started process 446 to run task
[2023-05-04T02:20:01.520+0000] {standard_task_runner.py:82} INFO - Running: ['***', 'tasks', 'run', 'train_ml_pipeline', 'train_model', 'scheduled__2023-05-02T00:00:00+00:00', '--job-id', '12', '--raw', '--subdir', 'DAGS_FOLDER/machine_learning_trainig_dag_Septembre.py', '--cfg-path', '/tmp/tmp09sovj7k']
[2023-05-04T02:20:01.524+0000] {standard_task_runner.py:83} INFO - Job 12: Subtask train_model
[2023-05-04T02:20:01.613+0000] {task_command.py:389} INFO - Running <TaskInstance: train_ml_pipeline.train_model scheduled__2023-05-02T00:00:00+00:00 [running]> on host e8a079a426a7
[2023-05-04T02:20:01.696+0000] {taskinstance.py:1511} INFO - Exporting the following env vars:
AIRFLOW_CTX_DAG_OWNER=***
AIRFLOW_CTX_DAG_ID=train_ml_pipeline
AIRFLOW_CTX_TASK_ID=train_model
AIRFLOW_CTX_EXECUTION_DATE=2023-05-02T00:00:00+00:00
AIRFLOW_CTX_TRY_NUMBER=1
AIRFLOW_CTX_DAG_RUN_ID=scheduled__2023-05-02T00:00:00+00:00
[2023-05-04T02:20:04.606+0000] {taskinstance.py:1772} ERROR - Task failed with exception
Traceback (most recent call last):
  File "/home/airflow/.local/lib/python3.10/site-packages/airflow/operators/python.py", line 175, in execute
    return_value = self.execute_callable()
  File "/home/airflow/.local/lib/python3.10/site-packages/airflow/operators/python.py", line 192, in execute_callable
    return self.python_callable(*self.op_args, **self.op_kwargs)
  File "/opt/airflow/dags/script.py", line 41, in train_model
    run = wandb.init()
  File "/home/airflow/.local/lib/python3.10/site-packages/wandb/sdk/wandb_init.py", line 1169, in init
    raise e
  File "/home/airflow/.local/lib/python3.10/site-packages/wandb/sdk/wandb_init.py", line 1146, in init
    wi.setup(kwargs)
  File "/home/airflow/.local/lib/python3.10/site-packages/wandb/sdk/wandb_init.py", line 289, in setup
    wandb_login._login(
  File "/home/airflow/.local/lib/python3.10/site-packages/wandb/sdk/wandb_login.py", line 298, in _login
    wlogin.prompt_api_key()
  File "/home/airflow/.local/lib/python3.10/site-packages/wandb/sdk/wandb_login.py", line 228, in prompt_api_key
    raise UsageError("api_key not configured (no-tty). call " + directive)
wandb.errors.UsageError: api_key not configured (no-tty). call wandb.login(key=[your_api_key])
[2023-05-04T02:20:04.617+0000] {taskinstance.py:1322} INFO - Marking task as UP_FOR_RETRY. dag_id=train_ml_pipeline, task_id=train_model, execution_date=20230502T000000, start_date=20230504T022001, end_date=20230504T022004
[2023-05-04T02:20:04.636+0000] {standard_task_runner.py:100} ERROR - Failed to execute job 12 for task train_model (api_key not configured (no-tty). call wandb.login(key=[your_api_key]); 446)
[2023-05-04T02:20:04.702+0000] {local_task_job.py:159} INFO - Task exited with return code 1
[2023-05-04T02:20:04.755+0000] {taskinstance.py:2582} INFO - 0 downstream tasks scheduled from follow-on schedule check
