[2023-05-04T02:59:56.714+0000] {taskinstance.py:1087} INFO - Dependencies all met for <TaskInstance: train_ml_pipeline.train_model manual__2023-05-04T02:54:26.984327+00:00 [queued]>
[2023-05-04T02:59:56.730+0000] {taskinstance.py:1087} INFO - Dependencies all met for <TaskInstance: train_ml_pipeline.train_model manual__2023-05-04T02:54:26.984327+00:00 [queued]>
[2023-05-04T02:59:56.730+0000] {taskinstance.py:1283} INFO - 
--------------------------------------------------------------------------------
[2023-05-04T02:59:56.730+0000] {taskinstance.py:1284} INFO - Starting attempt 2 of 2
[2023-05-04T02:59:56.730+0000] {taskinstance.py:1285} INFO - 
--------------------------------------------------------------------------------
[2023-05-04T02:59:56.744+0000] {taskinstance.py:1304} INFO - Executing <Task(PythonOperator): train_model> on 2023-05-04 02:54:26.984327+00:00
[2023-05-04T02:59:56.767+0000] {standard_task_runner.py:55} INFO - Started process 305 to run task
[2023-05-04T02:59:56.771+0000] {standard_task_runner.py:82} INFO - Running: ['***', 'tasks', 'run', 'train_ml_pipeline', 'train_model', 'manual__2023-05-04T02:54:26.984327+00:00', '--job-id', '39', '--raw', '--subdir', 'DAGS_FOLDER/machine_learning_trainig_dag_Septembre.py', '--cfg-path', '/tmp/tmptmlqtacf']
[2023-05-04T02:59:56.776+0000] {standard_task_runner.py:83} INFO - Job 39: Subtask train_model
[2023-05-04T02:59:56.849+0000] {task_command.py:389} INFO - Running <TaskInstance: train_ml_pipeline.train_model manual__2023-05-04T02:54:26.984327+00:00 [running]> on host 877f9e454e4e
[2023-05-04T02:59:56.920+0000] {taskinstance.py:1511} INFO - Exporting the following env vars:
AIRFLOW_CTX_DAG_OWNER=***
AIRFLOW_CTX_DAG_ID=train_ml_pipeline
AIRFLOW_CTX_TASK_ID=train_model
AIRFLOW_CTX_EXECUTION_DATE=2023-05-04T02:54:26.984327+00:00
AIRFLOW_CTX_TRY_NUMBER=2
AIRFLOW_CTX_DAG_RUN_ID=manual__2023-05-04T02:54:26.984327+00:00
[2023-05-04T02:59:56.937+0000] {logging_mixin.py:137} INFO - None
[2023-05-04T02:59:59.425+0000] {taskinstance.py:1772} ERROR - Task failed with exception
Traceback (most recent call last):
  File "/home/airflow/.local/lib/python3.10/site-packages/airflow/operators/python.py", line 175, in execute
    return_value = self.execute_callable()
  File "/home/airflow/.local/lib/python3.10/site-packages/airflow/operators/python.py", line 192, in execute_callable
    return self.python_callable(*self.op_args, **self.op_kwargs)
  File "/opt/airflow/dags/script.py", line 43, in train_model
    wandb.login(key=os.environ.get('WANDB_API_KEY'))
  File "/home/airflow/.local/lib/python3.10/site-packages/wandb/sdk/wandb_login.py", line 77, in login
    configured = _login(**kwargs)
  File "/home/airflow/.local/lib/python3.10/site-packages/wandb/sdk/wandb_login.py", line 298, in _login
    wlogin.prompt_api_key()
  File "/home/airflow/.local/lib/python3.10/site-packages/wandb/sdk/wandb_login.py", line 228, in prompt_api_key
    raise UsageError("api_key not configured (no-tty). call " + directive)
wandb.errors.UsageError: api_key not configured (no-tty). call wandb.login(key=[your_api_key])
[2023-05-04T02:59:59.439+0000] {taskinstance.py:1322} INFO - Marking task as FAILED. dag_id=train_ml_pipeline, task_id=train_model, execution_date=20230504T025426, start_date=20230504T025956, end_date=20230504T025959
[2023-05-04T02:59:59.454+0000] {standard_task_runner.py:100} ERROR - Failed to execute job 39 for task train_model (api_key not configured (no-tty). call wandb.login(key=[your_api_key]); 305)
[2023-05-04T02:59:59.514+0000] {local_task_job.py:159} INFO - Task exited with return code 1
[2023-05-04T02:59:59.545+0000] {taskinstance.py:2582} INFO - 0 downstream tasks scheduled from follow-on schedule check
