[2023-05-04T03:27:10.089+0000] {taskinstance.py:1087} INFO - Dependencies all met for <TaskInstance: train_ml_pipeline.train_model manual__2023-05-04T03:26:51.734702+00:00 [queued]>
[2023-05-04T03:27:10.102+0000] {taskinstance.py:1087} INFO - Dependencies all met for <TaskInstance: train_ml_pipeline.train_model manual__2023-05-04T03:26:51.734702+00:00 [queued]>
[2023-05-04T03:27:10.102+0000] {taskinstance.py:1283} INFO - 
--------------------------------------------------------------------------------
[2023-05-04T03:27:10.103+0000] {taskinstance.py:1284} INFO - Starting attempt 1 of 2
[2023-05-04T03:27:10.103+0000] {taskinstance.py:1285} INFO - 
--------------------------------------------------------------------------------
[2023-05-04T03:27:10.123+0000] {taskinstance.py:1304} INFO - Executing <Task(PythonOperator): train_model> on 2023-05-04 03:26:51.734702+00:00
[2023-05-04T03:27:10.146+0000] {standard_task_runner.py:55} INFO - Started process 151 to run task
[2023-05-04T03:27:10.150+0000] {standard_task_runner.py:82} INFO - Running: ['***', 'tasks', 'run', 'train_ml_pipeline', 'train_model', 'manual__2023-05-04T03:26:51.734702+00:00', '--job-id', '59', '--raw', '--subdir', 'DAGS_FOLDER/machine_learning_trainig_dag_Septembre.py', '--cfg-path', '/tmp/tmpcyuv_1aq']
[2023-05-04T03:27:10.154+0000] {standard_task_runner.py:83} INFO - Job 59: Subtask train_model
[2023-05-04T03:27:10.221+0000] {task_command.py:389} INFO - Running <TaskInstance: train_ml_pipeline.train_model manual__2023-05-04T03:26:51.734702+00:00 [running]> on host 2b8fae96b182
[2023-05-04T03:27:10.293+0000] {taskinstance.py:1511} INFO - Exporting the following env vars:
AIRFLOW_CTX_DAG_OWNER=***
AIRFLOW_CTX_DAG_ID=train_ml_pipeline
AIRFLOW_CTX_TASK_ID=train_model
AIRFLOW_CTX_EXECUTION_DATE=2023-05-04T03:26:51.734702+00:00
AIRFLOW_CTX_TRY_NUMBER=1
AIRFLOW_CTX_DAG_RUN_ID=manual__2023-05-04T03:26:51.734702+00:00
[2023-05-04T03:27:10.306+0000] {logging_mixin.py:137} INFO - None
[2023-05-04T03:27:10.307+0000] {taskinstance.py:1772} ERROR - Task failed with exception
Traceback (most recent call last):
  File "/home/airflow/.local/lib/python3.10/site-packages/airflow/operators/python.py", line 175, in execute
    return_value = self.execute_callable()
  File "/home/airflow/.local/lib/python3.10/site-packages/airflow/operators/python.py", line 192, in execute_callable
    return self.python_callable(*self.op_args, **self.op_kwargs)
  File "/opt/airflow/dags/script.py", line 47, in train_model
    datetime = datetime.now().strftime("%Y-%m-%d-%H-%M-%S")
UnboundLocalError: local variable 'datetime' referenced before assignment
[2023-05-04T03:27:10.315+0000] {taskinstance.py:1322} INFO - Marking task as UP_FOR_RETRY. dag_id=train_ml_pipeline, task_id=train_model, execution_date=20230504T032651, start_date=20230504T032710, end_date=20230504T032710
[2023-05-04T03:27:10.335+0000] {standard_task_runner.py:100} ERROR - Failed to execute job 59 for task train_model (local variable 'datetime' referenced before assignment; 151)
[2023-05-04T03:27:10.401+0000] {local_task_job.py:159} INFO - Task exited with return code 1
[2023-05-04T03:27:10.429+0000] {taskinstance.py:2582} INFO - 0 downstream tasks scheduled from follow-on schedule check
