[2023-05-04T03:24:39.788+0000] {taskinstance.py:1087} INFO - Dependencies all met for <TaskInstance: train_ml_pipeline.train_model manual__2023-05-04T03:24:20.009289+00:00 [queued]>
[2023-05-04T03:24:39.798+0000] {taskinstance.py:1087} INFO - Dependencies all met for <TaskInstance: train_ml_pipeline.train_model manual__2023-05-04T03:24:20.009289+00:00 [queued]>
[2023-05-04T03:24:39.798+0000] {taskinstance.py:1283} INFO - 
--------------------------------------------------------------------------------
[2023-05-04T03:24:39.798+0000] {taskinstance.py:1284} INFO - Starting attempt 1 of 2
[2023-05-04T03:24:39.798+0000] {taskinstance.py:1285} INFO - 
--------------------------------------------------------------------------------
[2023-05-04T03:24:39.811+0000] {taskinstance.py:1304} INFO - Executing <Task(PythonOperator): train_model> on 2023-05-04 03:24:20.009289+00:00
[2023-05-04T03:24:39.825+0000] {standard_task_runner.py:55} INFO - Started process 120 to run task
[2023-05-04T03:24:39.829+0000] {standard_task_runner.py:82} INFO - Running: ['***', 'tasks', 'run', 'train_ml_pipeline', 'train_model', 'manual__2023-05-04T03:24:20.009289+00:00', '--job-id', '54', '--raw', '--subdir', 'DAGS_FOLDER/machine_learning_trainig_dag_Septembre.py', '--cfg-path', '/tmp/tmpkm0ap9cx']
[2023-05-04T03:24:39.831+0000] {standard_task_runner.py:83} INFO - Job 54: Subtask train_model
[2023-05-04T03:24:39.891+0000] {task_command.py:389} INFO - Running <TaskInstance: train_ml_pipeline.train_model manual__2023-05-04T03:24:20.009289+00:00 [running]> on host ba099f9df9d9
[2023-05-04T03:24:39.955+0000] {taskinstance.py:1511} INFO - Exporting the following env vars:
AIRFLOW_CTX_DAG_OWNER=***
AIRFLOW_CTX_DAG_ID=train_ml_pipeline
AIRFLOW_CTX_TASK_ID=train_model
AIRFLOW_CTX_EXECUTION_DATE=2023-05-04T03:24:20.009289+00:00
AIRFLOW_CTX_TRY_NUMBER=1
AIRFLOW_CTX_DAG_RUN_ID=manual__2023-05-04T03:24:20.009289+00:00
[2023-05-04T03:24:39.970+0000] {logging_mixin.py:137} INFO - None
[2023-05-04T03:24:39.971+0000] {taskinstance.py:1772} ERROR - Task failed with exception
Traceback (most recent call last):
  File "/home/airflow/.local/lib/python3.10/site-packages/airflow/operators/python.py", line 175, in execute
    return_value = self.execute_callable()
  File "/home/airflow/.local/lib/python3.10/site-packages/airflow/operators/python.py", line 192, in execute_callable
    return self.python_callable(*self.op_args, **self.op_kwargs)
  File "/opt/airflow/dags/script.py", line 46, in train_model
    datetime = datetime.now().strftime("%Y-%m-%d-%H-%M-%S")
UnboundLocalError: local variable 'datetime' referenced before assignment
[2023-05-04T03:24:39.979+0000] {taskinstance.py:1322} INFO - Marking task as UP_FOR_RETRY. dag_id=train_ml_pipeline, task_id=train_model, execution_date=20230504T032420, start_date=20230504T032439, end_date=20230504T032439
[2023-05-04T03:24:39.990+0000] {standard_task_runner.py:100} ERROR - Failed to execute job 54 for task train_model (local variable 'datetime' referenced before assignment; 120)
[2023-05-04T03:24:40.040+0000] {local_task_job.py:159} INFO - Task exited with return code 1
[2023-05-04T03:24:40.064+0000] {taskinstance.py:2582} INFO - 0 downstream tasks scheduled from follow-on schedule check
