[2023-05-04T02:19:57.501+0000] {taskinstance.py:1087} INFO - Dependencies all met for <TaskInstance: train_ml_pipeline.train_model manual__2023-05-04T02:19:25.612905+00:00 [queued]>
[2023-05-04T02:19:57.519+0000] {taskinstance.py:1087} INFO - Dependencies all met for <TaskInstance: train_ml_pipeline.train_model manual__2023-05-04T02:19:25.612905+00:00 [queued]>
[2023-05-04T02:19:57.520+0000] {taskinstance.py:1283} INFO - 
--------------------------------------------------------------------------------
[2023-05-04T02:19:57.520+0000] {taskinstance.py:1284} INFO - Starting attempt 1 of 2
[2023-05-04T02:19:57.520+0000] {taskinstance.py:1285} INFO - 
--------------------------------------------------------------------------------
[2023-05-04T02:19:57.550+0000] {taskinstance.py:1304} INFO - Executing <Task(PythonOperator): train_model> on 2023-05-04 02:19:25.612905+00:00
[2023-05-04T02:19:57.585+0000] {standard_task_runner.py:55} INFO - Started process 404 to run task
[2023-05-04T02:19:57.592+0000] {standard_task_runner.py:82} INFO - Running: ['***', 'tasks', 'run', 'train_ml_pipeline', 'train_model', 'manual__2023-05-04T02:19:25.612905+00:00', '--job-id', '11', '--raw', '--subdir', 'DAGS_FOLDER/machine_learning_trainig_dag_Septembre.py', '--cfg-path', '/tmp/tmpu3q2lvam']
[2023-05-04T02:19:57.597+0000] {standard_task_runner.py:83} INFO - Job 11: Subtask train_model
[2023-05-04T02:19:57.738+0000] {task_command.py:389} INFO - Running <TaskInstance: train_ml_pipeline.train_model manual__2023-05-04T02:19:25.612905+00:00 [running]> on host e8a079a426a7
[2023-05-04T02:19:57.856+0000] {taskinstance.py:1511} INFO - Exporting the following env vars:
AIRFLOW_CTX_DAG_OWNER=***
AIRFLOW_CTX_DAG_ID=train_ml_pipeline
AIRFLOW_CTX_TASK_ID=train_model
AIRFLOW_CTX_EXECUTION_DATE=2023-05-04T02:19:25.612905+00:00
AIRFLOW_CTX_TRY_NUMBER=1
AIRFLOW_CTX_DAG_RUN_ID=manual__2023-05-04T02:19:25.612905+00:00
[2023-05-04T02:20:00.991+0000] {taskinstance.py:1772} ERROR - Task failed with exception
Traceback (most recent call last):
  File "/home/airflow/.local/lib/python3.10/site-packages/airflow/operators/python.py", line 175, in execute
    return_value = self.execute_callable()
  File "/home/airflow/.local/lib/python3.10/site-packages/airflow/operators/python.py", line 192, in execute_callable
    return self.python_callable(*self.op_args, **self.op_kwargs)
  File "/opt/airflow/dags/script.py", line 41, in train_model
    run = wandb.init()
  File "/home/airflow/.local/lib/python3.10/site-packages/wandb/sdk/wandb_init.py", line 1169, in init
    raise e
  File "/home/airflow/.local/lib/python3.10/site-packages/wandb/sdk/wandb_init.py", line 1146, in init
    wi.setup(kwargs)
  File "/home/airflow/.local/lib/python3.10/site-packages/wandb/sdk/wandb_init.py", line 289, in setup
    wandb_login._login(
  File "/home/airflow/.local/lib/python3.10/site-packages/wandb/sdk/wandb_login.py", line 298, in _login
    wlogin.prompt_api_key()
  File "/home/airflow/.local/lib/python3.10/site-packages/wandb/sdk/wandb_login.py", line 228, in prompt_api_key
    raise UsageError("api_key not configured (no-tty). call " + directive)
wandb.errors.UsageError: api_key not configured (no-tty). call wandb.login(key=[your_api_key])
[2023-05-04T02:20:01.012+0000] {taskinstance.py:1322} INFO - Marking task as UP_FOR_RETRY. dag_id=train_ml_pipeline, task_id=train_model, execution_date=20230504T021925, start_date=20230504T021957, end_date=20230504T022001
[2023-05-04T02:20:01.042+0000] {standard_task_runner.py:100} ERROR - Failed to execute job 11 for task train_model (api_key not configured (no-tty). call wandb.login(key=[your_api_key]); 404)
[2023-05-04T02:20:01.108+0000] {local_task_job.py:159} INFO - Task exited with return code 1
[2023-05-04T02:20:01.146+0000] {taskinstance.py:2582} INFO - 0 downstream tasks scheduled from follow-on schedule check
