[2023-05-04T02:33:07.765+0000] {taskinstance.py:1087} INFO - Dependencies all met for <TaskInstance: train_ml_pipeline.train_model manual__2023-05-04T02:32:36.748754+00:00 [queued]>
[2023-05-04T02:33:07.778+0000] {taskinstance.py:1087} INFO - Dependencies all met for <TaskInstance: train_ml_pipeline.train_model manual__2023-05-04T02:32:36.748754+00:00 [queued]>
[2023-05-04T02:33:07.778+0000] {taskinstance.py:1283} INFO - 
--------------------------------------------------------------------------------
[2023-05-04T02:33:07.778+0000] {taskinstance.py:1284} INFO - Starting attempt 1 of 2
[2023-05-04T02:33:07.778+0000] {taskinstance.py:1285} INFO - 
--------------------------------------------------------------------------------
[2023-05-04T02:33:07.791+0000] {taskinstance.py:1304} INFO - Executing <Task(PythonOperator): train_model> on 2023-05-04 02:32:36.748754+00:00
[2023-05-04T02:33:07.807+0000] {standard_task_runner.py:55} INFO - Started process 387 to run task
[2023-05-04T02:33:07.812+0000] {standard_task_runner.py:82} INFO - Running: ['***', 'tasks', 'run', 'train_ml_pipeline', 'train_model', 'manual__2023-05-04T02:32:36.748754+00:00', '--job-id', '21', '--raw', '--subdir', 'DAGS_FOLDER/machine_learning_trainig_dag_Septembre.py', '--cfg-path', '/tmp/tmp82zdtxta']
[2023-05-04T02:33:07.815+0000] {standard_task_runner.py:83} INFO - Job 21: Subtask train_model
[2023-05-04T02:33:07.874+0000] {task_command.py:389} INFO - Running <TaskInstance: train_ml_pipeline.train_model manual__2023-05-04T02:32:36.748754+00:00 [running]> on host a9dfe5bc497c
[2023-05-04T02:33:07.935+0000] {taskinstance.py:1511} INFO - Exporting the following env vars:
AIRFLOW_CTX_DAG_OWNER=***
AIRFLOW_CTX_DAG_ID=train_ml_pipeline
AIRFLOW_CTX_TASK_ID=train_model
AIRFLOW_CTX_EXECUTION_DATE=2023-05-04T02:32:36.748754+00:00
AIRFLOW_CTX_TRY_NUMBER=1
AIRFLOW_CTX_DAG_RUN_ID=manual__2023-05-04T02:32:36.748754+00:00
[2023-05-04T02:33:10.221+0000] {taskinstance.py:1772} ERROR - Task failed with exception
Traceback (most recent call last):
  File "/home/airflow/.local/lib/python3.10/site-packages/airflow/operators/python.py", line 175, in execute
    return_value = self.execute_callable()
  File "/home/airflow/.local/lib/python3.10/site-packages/airflow/operators/python.py", line 192, in execute_callable
    return self.python_callable(*self.op_args, **self.op_kwargs)
  File "/opt/airflow/dags/script.py", line 42, in train_model
    wandb.login(key=os.environ.get('WANDB_API_KEY'))
  File "/home/airflow/.local/lib/python3.10/site-packages/wandb/sdk/wandb_login.py", line 77, in login
    configured = _login(**kwargs)
  File "/home/airflow/.local/lib/python3.10/site-packages/wandb/sdk/wandb_login.py", line 298, in _login
    wlogin.prompt_api_key()
  File "/home/airflow/.local/lib/python3.10/site-packages/wandb/sdk/wandb_login.py", line 228, in prompt_api_key
    raise UsageError("api_key not configured (no-tty). call " + directive)
wandb.errors.UsageError: api_key not configured (no-tty). call wandb.login(key=[your_api_key])
[2023-05-04T02:33:10.234+0000] {taskinstance.py:1322} INFO - Marking task as UP_FOR_RETRY. dag_id=train_ml_pipeline, task_id=train_model, execution_date=20230504T023236, start_date=20230504T023307, end_date=20230504T023310
[2023-05-04T02:33:10.259+0000] {standard_task_runner.py:100} ERROR - Failed to execute job 21 for task train_model (api_key not configured (no-tty). call wandb.login(key=[your_api_key]); 387)
[2023-05-04T02:33:10.308+0000] {local_task_job.py:159} INFO - Task exited with return code 1
[2023-05-04T02:33:10.332+0000] {taskinstance.py:2582} INFO - 0 downstream tasks scheduled from follow-on schedule check
